<?xml version="1.0" ?>
<!-- =================================================================================== -->
<!-- |    This document was autogenerated by xacro from tb_descript_temp.urdf          | -->
<!-- |    EDITING THIS FILE BY HAND IS NOT RECOMMENDED                                 | -->
<!-- =================================================================================== -->
<robot name="turtlebot3_burger">
  <!-- Robot Base -->
  <link name="base_link">
    <visual>
      <geometry>
        <box size="0.138 0.178 0.192"/>
      </geometry>
      <material name="Orange">
        <color rgba="1.0 0.4235 0.0392 1.0"/>
      </material>
    </visual>
  </link>
  <!-- Robot Footprint -->
  <!-- no parameters, used for pkgs-->
  <link name="base_footprint"/>
  <joint name="base_joint" type="fixed">
    <parent link="base_footprint"/>
    <child link="base_link"/>
    <origin rpy="0 0 0" xyz="0.0 0.0 -0.084"/>
  </joint>
  <link name="drivewhl_l_link">
    <visual>
      <origin rpy="1.5707963267948966 0 0" xyz="0 0 0"/>
      <geometry>
        <cylinder length="0.066" radius="0.034"/>
      </geometry>
      <material name="Gray">
        <color rgba="0.5 0.5 0.5 1.0"/>
      </material>
    </visual>
  </link>
  <joint name="drivewhl_l_joint" type="continuous">
    <parent link="base_link"/>
    <child link="drivewhl_l_link"/>
    <origin rpy="0 0 0" xyz="-0.006 0.11399999999999999 -0.05"/>
    <axis xyz="0 1 0"/>
  </joint>
  <link name="drivewhl_r_link">
    <visual>
      <origin rpy="1.5707963267948966 0 0" xyz="0 0 0"/>
      <geometry>
        <cylinder length="0.066" radius="0.034"/>
      </geometry>
      <material name="Gray">
        <color rgba="0.5 0.5 0.5 1.0"/>
      </material>
    </visual>
  </link>
  <joint name="drivewhl_r_joint" type="continuous">
    <parent link="base_link"/>
    <child link="drivewhl_r_link"/>
    <origin rpy="0 0 0" xyz="-0.006 -0.11399999999999999 -0.05"/>
    <axis xyz="0 1 0"/>
  </joint>
  <!-- Caster Wheel Descriptions -->
  <link name="front_caster">
    <visual>
      <geometry>
        <sphere radius="-0.011999999999999997"/>
      </geometry>
      <material name="Cyan">
        <color rgba="0 1.0 1.0 1.0"/>
      </material>
    </visual>
  </link>
  <joint name="caster_joint" type="fixed">
    <parent link="base_link"/>
    <child link="front_caster"/>
    <origin rpy="0 0 0" xyz="0.089 0.0 -0.096"/>
  </joint>
  <!-- collision area -->
  <collision>
    <!-- base collision, mass in kg-->
    <geometry>
      <box size="0.138 0.178 0.192"/>
    </geometry>
  </collision>
  <inertial>
    <origin rpy="1.5707963267948966 0 1.5707963267948966" xyz="0 0 0"/>
    <mass value="mass"/>
    <inertia ixx="0.08333333333333333 * (height * height + depth * depth)}" ixy="0" ixz="0" iyy="0.004227333333333333" iyz="0.0" izz="0.005712333333333333"/>
  </inertial>
  <collision>
    <!-- wheel collision-->
    <geometry>
      <cylinder length="0.066" radius="0.034"/>
    </geometry>
  </collision>
  <inertial>
    <origin rpy="1.5707963267948966 0 0" xyz="0 0 0"/>
    <mass value="0.05"/>
    <inertia ixx="3.2600000000000006e-05" ixy="0" iyy="3.2600000000000006e-05" iyz="0" izz="2.8900000000000005e-05"/>
  </inertial>
  <collision>
    <!-- caster ball-->
    <geometry>
      <geometry>
        <sphere radius="-0.011999999999999997s"/>
      </geometry>
    </geometry>
  </collision>
  <inertial>
    <mass value="0.005"/>
    <inertia ixx="2.879999999999998e-07" ixy="0.0" ixz="0.0" iyy="2.879999999999998e-07" iyz="0.0" izz="2.879999999999998e-07"/>
  </inertial>
  <!-- Odometry -->
  <link name="imu_link">
    <visual>
      <geometry>
        <box size="0.1 0.1 0.1"/>
      </geometry>
    </visual>
    <collision>
      <geometry>
        <box size="0.1 0.1 0.1"/>
      </geometry>
    </collision>
    <inertial>
      <origin rpy="1.5707963267948966 0 1.5707963267948966" xyz="0 0 0"/>
      <mass value="mass"/>
      <inertia ixx="0.008333333333333333 * (height * height + depth * depth)}" ixy="0" ixz="0" iyy="0.0001666666666666667" iyz="0.0" izz="0.0001666666666666667"/>
    </inertial>
  </link>
  <joint name="imu_joint" type="fixed">
    <parent link="base_link"/>
    <child link="imu_link"/>
    <origin rpy="0 0 0" xyz="-0.032 0 0.172"/>
  </joint>
  <!-- Sensors -->
  <link name="lidar_link">
    <inertial>
      <origin rpy="0 0 0" xyz="0 0 0"/>
      <mass value="0.114"/>
      <inertia ixx="0.001" ixy="0" ixz="0" iyy="0.001" iyz="0" izz="0.001"/>
    </inertial>
    <collision>
      <origin rpy="0 0 0" xyz="0.015 0 -0.0065"/>
      <geometry>
        <cylinder length="0.0315" radius="0.055"/>
      </geometry>
    </collision>
    <visual>
      <origin rpy="0 0 0" xyz="0 0 0"/>
      <geometry>
        <cylinder length="0.0955" radius="0.0695"/>
      </geometry>
    </visual>
  </link>
  <joint name="lidar_joint" type="fixed">
    <parent link="base_link"/>
    <child link="lidar_link"/>
    <origin rpy="0 0 0" xyz="-0.032 0 0.172"/>
  </joint>
</robot>
