<?xml version="1.0">
<robot name="turtlebot3_burger"
    xmlns:xacro="http://ros.org/wiki/xacro">

    <!-- robot constants, values are in meters-->
    <xacro:property name="base_width" value="0.178"/>
    <xacro:property name="base_length" value="0.138"/>
    <xacro:property name="base_heght" value="0.192"/>

    <xacro:property name="wheel_radius" value="0.032"/>
    <xacro:property name="wheel_width" value="0.066"/>
    <xacro:property name="wheel_ygap" value="0.025"/>
    <xacro:property name="wheel_zoff" value="0.05"/>
    <xacro:property name="wheel_xoff" value="0.006"/>

    <xacro:property name="caster_xoff" value="0.089"/>

    <!-- Robot Base -->
    <link name="base_link">
        <visual>
            <geometry>
                <box size="${base_length} ${base_width} ${base_height}"/>
            </geometry>
            <material name="black">
                <color rgba="0.0 0.0 0.0 0.0"/>
            </material>
        </visual>
    </link>

    <!-- Robot Footprint -->
    <link name="base_footprint"/>
    <!-- no parameters, used for pkgs-->

    <joint name="base_joint" type="fixed">
        <parent link="base_link"/>
        <child link="base_footprint"/>
        <origin xyz="0.0 0.0 ${wheel_radius+wheel_zoff)}" rpy="0.0 0.0 0.0"/>
    </joint>

    <!-- Wheel despcriptions -->
    <xacro:macro name="wheel", params="prefix x_reflect y_reflect">
        <link name="${prefix}_link">
            <visual>
                <origin xyz="0 0 0" rpy="$pi/2 0 0"/>
                <geometry>
                    <cylinder radius="${wheel_radius}" length="${wheel_length}"/>
                </geometry>
                <material name="Gray">
                    <color rgba="0.5 0.5 0.5 1.0"/>
                </material>
            </visual>
        </link>

        <joint name="${prefix}_joint" type="continuous">
            <parent link="base_link"/>
            <child link="${prefix}_link"/>
            <origin xyz="${x_reflect*wheel_xoff} ${y_reflect*(base_width/2+wheel_ygap)}" rpy="0.0 0.0 0.0"/>
            <axis xyz="0 1 0"/>
        </joint>
    </xacro>

    <xacro:wheel prefix="drivewhl_l" x_reflect="-1" y_reflect="1"/>
    <xacro:wheel prefix="drivewhl_r" x_reflect="-1" y_reflect="-1"/>

    <!-- Caster Wheel Descriptions -->
    <link name="front_caster">
        <visual>
            <geometry>
                <sphere radius="${(wheel_radius+wheel_zoff-(base_height/2))}}"/>
            </geometry>
            <material name="Cyan">
                <color rgba="0.0 1.0 1.0 1.0"/>
            </material>
        </visual>
    </link>

    <joint name="caster_joint" type="fixed">
        <parent link="base_link"/>
        <child link="front_caster"/>
        <origin xyz="${caster_xoff} 0.0 ${-(base_height/2)}" rpy="0.0 0.0 0.0"/>
    </joint>


</robot>